Workbook

Sheet Summary
A1: Monthly Summaries- Revenue
A2: Brand | B2: # of Listings | C2: Monthly Rev | D2: Estimated 12mo Revenue | E2: Monthly Units | F2: Monthly Rev Market Share % | G2: Price Per Unit | H2: Total Reviews | I2: Avg Rating
A3: teslong | B3: 38 | C3: 732750.73 | D3: 8793008.8 | E3: 7511 | F3: 0.1827 | G3: 97.56 | H3: 26364 | I3: 4.4
A4: depstech | B4: 28 | C4: 716858.49 | D4: 8602301.9 | E4: 8951 | F4: 0.1787 | G4: 80.09 | H4: 51524 | I4: 4.5
A5: dxztoz | B5: 3 | C5: 262983.69 | D5: 3155804.3 | E5: 1836 | F5: 0.0656 | G5: 143.24 | H5: 1104 | I5: 4.5
A6: mugeasy | B6: 6 | C6: 189692.89 | D6: 2276314.7 | E6: 4867 | F6: 0.0473 | G6: 38.98 | H6: 4745 | I6: 4.2
A7: daxiongmao | B7: 8 | C7: 182592.49 | D7: 2191109.9 | E7: 4817 | F7: 0.0455 | G7: 37.91 | H7: 6610 | I7: 4.3
A8: kinpthy | B8: 5 | C8: 176338.5 | D8: 2116062 | E8: 6150 | F8: 0.044 | G8: 28.67 | H8: 11599 | I8: 4.4
A9: hijoy | B9: 2 | C9: 129193 | D9: 1550316 | E9: 914 | F9: 0.0322 | G9: 141.35 | H9: 297 | I9: 4.7
A10: winwend | B10: 2 | C10: 125293.46 | D10: 1503521.5 | E10: 3343 | F10: 0.0312 | G10: 37.48 | H10: 734 | I10: 4.6
A11: ujoyok | B11: 1 | C11: 109263.61 | D11: 1311163.3 | E11: 841 | F11: 0.0272 | G11: 129.92 | H11: 102 | I11: 4.7
A12: kaiweets | B12: 1 | C12: 100789.81 | D12: 1209477.7 | E12: 840 | F12: 0.0251 | G12: 119.99 | H12: 152 | I12: 4.3
A14: Total | B14: =SUM(B2:B12) -> 94 | C14: =SUM(C3:C12) -> 2725756.7 | D14: =SUM(D3:D12) -> 32709080 | E14: =SUM(E3:E12) -> 40070 | F14: =SUM(F3:F12) -> 0.6795 | G14: =AVERAGE(G3:G12) -> 85.519 | H14: =SUM(H3:H12) -> 103231 | I14: =AVERAGE(I3:I12) -> 4.46
A15: Market Total | B15: 804 | C15: 4011200 | E15: 73568 | G15: =C15/E15 -> 54.523706 | H15: 225998 | I15: 4.1498339
A17: Monthly Summary - Units
A18: Brand | B18: # of Listings | C18: Monthly Rev | D18: Estimated 12mo Units | E18: Monthly Units | F18: Monthly Unit Market Share % | G18: Price Per Unit | H18: Reviews | I18: Avg Rating
A19: depstech | B19: 28 | C19: 716858.49 | D19: 107412 | E19: 8951 | F19: 0.1217 | G19: 80.09 | H19: 51524 | I19: 4.5
A20: teslong | B20: 38 | C20: 732750.73 | D20: 90132 | E20: 7511 | F20: 0.1021 | G20: 97.56 | H20: 26364 | I20: 4.4
A21: kinpthy | B21: 5 | C21: 176338.5 | D21: 73800 | E21: 6150 | F21: 0.0836 | G21: 28.67 | H21: 11599 | I21: 4.4
A22: mugeasy | B22: 6 | C22: 189692.89 | D22: 58404 | E22: 4867 | F22: 0.0662 | G22: 38.98 | H22: 4745 | I22: 4.2
A23: daxiongmao | B23: 8 | C23: 182592.49 | D23: 57804 | E23: 4817 | F23: 0.0655 | G23: 37.91 | H23: 6610 | I23: 4.3
A24: winwend | B24: 2 | C24: 125293.46 | D24: 40116 | E24: 3343 | F24: 0.0454 | G24: 37.48 | H24: 734 | I24: 4.6
A25: acoath | B25: 4 | C25: 66407.39 | D25: 28464 | E25: 2372 | F25: 0.0322 | G25: 28 | H25: 371 | I25: 4.4
A26: nidage | B26: 11 | C26: 97109.4 | D26: 25464 | E26: 2122 | F26: 0.0288 | G26: 45.76 | H26: 14314 | I26: 4.4
A27: pancellent | B27: 4 | C27: 49057.52 | D27: 24396 | E27: 2033 | F27: 0.0276 | G27: 24.13 | H27: 3564 | I27: 4.3
A28: ennovor | B28: 5 | C28: 57052.65 | D28: 23964 | E28: 1997 | F28: 0.0271 | G28: 28.57 | H28: 4824 | I28: 4.5
A30: Total | B30: =SUM(B18:B28) -> 111 | C30: =SUM(C19:C28) -> 2393153.5 | D30: =SUM(D19:D28) -> 529956 | E30: =SUM(E19:E28) -> 44163 | F30: =SUM(F19:F28) -> 0.6002 | G30: =AVERAGE(G19:G28) -> 44.715 | H30: =SUM(H19:H28) -> 124649 | I30: =AVERAGE(I19:I28) -> 4.4

Sheet Top 50
A1: Rank By Monthly Revenue - ONLY
A2: Ranking | B2: ASIN | C2: Product Name | D2: Brand | E2: Type | F2: Price | G2: Est. Monthly Retail Rev | H2: Est. Monthly Units Sold | I2: # of Reviews | J2: Avg. Rating | K2: Column2 | L2: Link
A3: 1 | B3: B0CJY5C9QX | C3: Teslong Two-Way Articulating Borescope with Light, Industrial Endoscope Inspection Camera with Articulated Probe, Flexible Mechanic Fiber Optic Snake Scope Cam for Wall Automotive Engine Inspect-5FT | D3: teslong | E3: Articulation | F3: 129.97422 | G3: 307908.93 | H3: 2369 | I3: 484 | J3: 4.6 | K3: https://amazon.com/dp/B0CJY5C9QX | L3: =HYPERLINK(K3) -> https://amazon.com/dp/B0CJY5C9QX
A4: 2 | B4: B0B28HRSBP | C4: Two-Way Articulating Borescope, DXZtoz Industrial Endoscope with 0.33in Articulated Snake Camera, Video Inspection Scope with Light for Automotive Aircraft Mechanics- 5.5FT | D4: dxztoz | E4: Articulation | F4: 139.41909 | G4: 243843.99 | H4: 1749 | I4: 1053 | J4: 4.6 | K4: https://amazon.com/dp/B0B28HRSBP | L4: =HYPERLINK(K4) -> https://amazon.com/dp/B0B28HRSBP
A5: 3 | B5: B0928Q3T42 | C5: DEPSTECH Dual Lens Industrial Endoscope, 1080P Digital Borescope Inspection Camera, 7.9mm IP67 Waterproof Camera, Sewer Camera with 4.3" LCD Screen,7 LED Lights,16.5FT Semi-Rigid Cable,32GB Card-Black | D5: depstech | E5: Landscape | F5: 63.776025 | G5: 173598.34 | H5: 2722 | I5: 6096 | J5: 4.5 | K5: https://amazon.com/dp/B0928Q3T42 | L5: =HYPERLINK(K5) -> https://amazon.com/dp/B0928Q3T42
A6: 4 | B6: B0BS1CFFH8 | C6: Triple Lens Sewer Inspection Camera with 50FT Semi-Rigid Cable, DEPSTECH 5"IPS Screen Endoscope Camera with Lights, 1080P Industrial Borescope, Split Screen, Waterproof Drain Pipe Camera,Carrying Case | D6: depstech | E6: Landscape | F6: 129.94307 | G6: 145536.24 | H6: 1120 | I6: 1784 | J6: 4.4 | K6: https://amazon.com/dp/B0BS1CFFH8 | L6: =HYPERLINK(K6) -> https://amazon.com/dp/B0BS1CFFH8
A7: 5 | B7: B0CFF8Z1NF | C7: Endoscope Camera with Light, Inspection Borescope Camera with 4.3" IPS Screen, 1920P HD with 8 LED Lights, 16.4FT Semi-Rigid Cord Bore Scope, IP67 Waterproof Endoscope for Sewer, Tools(Orange) | D7: mugeasy | E7: Landscape | F7: 41.444117 | G7: 129844.42 | H7: 3133 | I7: 989 | J7: 4.6 | K7: https://amazon.com/dp/B0CFF8Z1NF | L7: =HYPERLINK(K7) -> https://amazon.com/dp/B0CFF8Z1NF
A8: 6 | B8: B0C4V5LWWL | C8: Endoscope Camera with Light, 1920P HD Borescope Tools with 8 Adjustable LED Lights, Endoscope with 16.4ft Semi-Rigid Snake Camera, IP67 Waterproof Inspection Borescope for iOS and Android-16.4ft | D8: kinpthy | E8: USB | F8: 25.99 | G8: 116955 | H8: 4500 | I8: 1548 | J8: 4.3 | K8: https://amazon.com/dp/B0C4V5LWWL | L8: =HYPERLINK(K8) -> https://amazon.com/dp/B0C4V5LWWL
A9: 7 | B9: B0DFHL8YN5 | C9: Two-Way Articulating Borescope with Light, UJOYOK Industrial Endoscope with Snake Scope Camera, Borescope Inspection Camera with Light for Automotive & Aircraft Mechanics, 5.5FT | D9: ujoyok | E9: Articulation | F9: 129.92106 | G9: 109263.61 | H9: 841 | I9: 102 | J9: 4.7 | K9: https://amazon.com/dp/B0DFHL8YN5 | L9: =HYPERLINK(K9) -> https://amazon.com/dp/B0DFHL8YN5
A10: 8 | B10: B0D9M3Q7FK | C10: Two-Way Articulating Borescope Camera with Light, KAIWEETS 0.33in Industrial Endoscope Camera with Light, 5FT Flexible Snake Inspection Scope for Automotive and Aircraft Mechanics | D10: kaiweets | E10: Articulation | F10: 119.98787 | G10: 100789.81 | H10: 840 | I10: 152 | J10: 4.3 | K10: https://amazon.com/dp/B0D9M3Q7FK | L10: =HYPERLINK(K10) -> https://amazon.com/dp/B0D9M3Q7FK
A11: 9 | B11: B0CP538LN1 | C11: WINWEND Endoscope Camera with Light - IP67 Waterproof Borescope Camera with 8 Adjustable LED Lights | 4.3" LCD Screen Borescope | HD 1080P Inspection Cameras with 16.5ft Semi-Rigid Cord Tools for Men | D11: winwend | E11: Handheld | F11: 37.597973 | G11: 93318.17 | H11: 2482 | I11: 531 | J11: 4.6 | K11: https://amazon.com/dp/B0CP538LN1 | L11: =HYPERLINK(K11) -> https://amazon.com/dp/B0CP538LN1
A12: 10 | B12: B0C3R381FC | C12: Endoscope Camera with Light, Borescope Camera with 4.3" IPS Screen, 1080P HD with 8 LED Lights, 16.4FT Semi-Rigid Cord Bore Scope, Tools for Men | D12: daxiongmao | E12: Landscape | F12: 37.149725 | G12: 90608.18 | H12: 2439 | I12: 2494 | J12: 4.4 | K12: https://amazon.com/dp/B0C3R381FC | L12: =HYPERLINK(K12) -> https://amazon.com/dp/B0C3R381FC
A13: 11 | B13: B07TV2BFVR | C13: Teslong Inspection Camera, Dual Lens Borescope Camera with Light, NTS300 5" IPS Industrial Endoscope, 1080P Waterproof Flexible Mechanic Fiber Optic Snake Scope Cam for Wall Automotive Engine (16.5FT) | D13: teslong | E13: Handheld | F13: 150.13255 | G13: 89629.13 | H13: 597 | I13: 3464 | J13: 4.6 | K13: https://amazon.com/dp/B07TV2BFVR | L13: =HYPERLINK(K13) -> https://amazon.com/dp/B07TV2BFVR
A14: 12 | B14: B0D59Y7B2D | C14: Hijoy Articulating Borescope Camera with Light - 5'' 1080P HD Display Industrial Endoscope Inspection Camera 5.5FT Snake Camera for Automotive HVAC and Industrial Mechanics | D14: hijoy | E14: Articulation | F14: 150.79807 | G14: 75700.63 | H14: 502 | I14: 70 | J14: 4.7 | K14: https://amazon.com/dp/B0D59Y7B2D | L14: =HYPERLINK(K14) -> https://amazon.com/dp/B0D59Y7B2D
... A52: 50 | B52: B07PBW52SF | C52: Oiiwak Endoscope Camera with Light, 5.5 mm Borescope, 4.3" IPS Screen HD Digital Snake Inspection Camera, IP67 Waterproof for Drain, Plumbing, Wall, Automotive- 3.5 m/11.5 ft | D52: oiiwak | E52: Portrait | F52: 50.048109 | G52: 17466.79 | H52: 349 | I52: 3482 | J52: 4.3 | K52: https://amazon.com/dp/B07PBW52SF | L52: =HYPERLINK(K52) -> https://amazon.com/dp/B07PBW52SF
A55: Rank By Monthly Units - ONLY
A56: Ranking | B56: ASIN | C56: Product Name | D56: Brand | E56: Type | F56: Price | G56: Est. Monthly Retail Rev | H56: Est. Monthly Units Sold | I56: # of Reviews | J56: Avg. Rating | K56: Column2 | L56: Link
A57: 1 | B57: B0C4V5LWWL | C57: Endoscope Camera with Light, 1920P HD Borescope Tools with 8 Adjustable LED Lights, Endoscope with 16.4ft Semi-Rigid Snake Camera, IP67 Waterproof Inspection Borescope for iOS and Android-16.4ft | D57: kinpthy | E57: USB | F57: 25.99 | G57: 116955 | H57: 4500 | I57: 1548 | J57: 4.3 | K57: https://amazon.com/dp/B0C4V5LWWL | L57: =HYPERLINK(K57) -> https://amazon.com/dp/B0C4V5LWWL
A58: 2 | B58: B0CFF8Z1NF | C58: Endoscope Camera with Light, Inspection Borescope Camera with 4.3" IPS Screen, 1920P HD with 8 LED Lights, 16.4FT Semi-Rigid Cord Bore Scope, IP67 Waterproof Endoscope for Sewer, Tools(Orange) | D58: mugeasy | E58: Landscape | F58: 41.444117 | G58: 129844.42 | H58: 3133 | I58: 989 | J58: 4.6 | K58: https://amazon.com/dp/B0CFF8Z1NF | L58: =HYPERLINK(K58) -> https://amazon.com/dp/B0CFF8Z1NF
A59: 3 | B59: B0928Q3T42 | C59: DEPSTECH Dual Lens Industrial Endoscope, 1080P Digital Borescope Inspection Camera, 7.9mm IP67 Waterproof Camera, Sewer Camera with 4.3" LCD Screen,7 LED Lights,16.5FT Semi-Rigid Cable,32GB Card-Black | D59: depstech | E59: Landscape | F59: 63.776025 | G59: 173598.34 | H59: 2722 | I59: 6096 | J59: 4.5 | K59: https://amazon.com/dp/B0928Q3T42 | L59: =HYPERLINK(K59) -> https://amazon.com/dp/B0928Q3T42
A60: 4 | B60: B0CP538LN1 | C60: WINWEND Endoscope Camera with Light - IP67 Waterproof Borescope Camera with 8 Adjustable LED Lights | 4.3" LCD Screen Borescope | HD 1080P Inspection Cameras with 16.5ft Semi-Rigid Cord Tools for Men | D60: winwend | E60: Handheld | F60: 37.597973 | G60: 93318.17 | H60: 2482 | I60: 531 | J60: 4.6 | K60: https://amazon.com/dp/B0CP538LN1 | L60: =HYPERLINK(K60) -> https://amazon.com/dp/B0CP538LN1
A61: 5 | B61: B0C3R381FC | C61: Endoscope Camera with Light, Borescope Camera with 4.3" IPS Screen, 1080P HD with 8 LED Lights, 16.4FT Semi-Rigid Cord Bore Scope, Tools for Men | D61: daxiongmao | E61: Landscape | F61: 37.149725 | G61: 90608.18 | H61: 2439 | I61: 2494 | J61: 4.4 | K61: https://amazon.com/dp/B0C3R381FC | L61: =HYPERLINK(K61) -> https://amazon.com/dp/B0C3R381FC
A62: 6 | B62: B0CJY5C9QX | C62: Teslong Two-Way Articulating Borescope with Light, Industrial Endoscope Inspection Camera with Articulated Probe, Flexible Mechanic Fiber Optic Snake Scope Cam for Wall Automotive Engine Inspect-5FT | D62: teslong | E62: Articulation | F62: 129.97422 | G62: 307908.93 | H62: 2369 | I62: 484 | J62: 4.6 | K62: https://amazon.com/dp/B0CJY5C9QX | L62: =HYPERLINK(K62) -> https://amazon.com/dp/B0CJY5C9QX
A63: 7 | B63: B0DGFBCH38 | C63: Acoath Endoscope Camera with Light, Dual-Lens 1920P HD Borescope with 8 Adjustable LED Lights, IP67 Waterproof Boroscope Inspection Tools, 16.4ft Semi-Rigid Snake Camera for iOS & Android | D63: acoath | E63: USB | F63: 26.93605 | G63: 52229 | H63: 1939 | I63: 165 | J63: 4.3 | K63: https://amazon.com/dp/B0DGFBCH38 | L63: =HYPERLINK(K63) -> https://amazon.com/dp/B0DGFBCH38
A64: 8 | B64: B0B28HRSBP | C64: Two-Way Articulating Borescope, DXZtoz Industrial Endoscope with 0.33in Articulated Snake Camera, Video Inspection Scope with Light for Automotive Aircraft Mechanics- 5.5FT | D64: dxztoz | E64: Articulation | F64: 139.41909 | G64: 243843.99 | H64: 1749 | I64: 1053 | J64: 4.6 | K64: https://amazon.com/dp/B0B28HRSBP | L64: =HYPERLINK(K64) -> https://amazon.com/dp/B0B28HRSBP
A65: 9 | B65: B0BXSMSS7M | C65: Endoscope Camera with Light, 1080P HD Borescope Tools with 8 Adjustable LED Lights, 4.3" Endoscope with 16.4ft Semi-Rigid Snake Camera, IP67 Waterproof Inspection Borescope, Gadgets for Men | D65: daxiongmao | E65: Handheld | F65: 38.009592 | G65: 63323.98 | H65: 1666 | I65: 1189 | J65: 4.4 | K65: https://amazon.com/dp/B0BXSMSS7M | L65: =HYPERLINK(K65) -> https://amazon.com/dp/B0BXSMSS7M
A66: 10 | B66: B0CG46T9ZF | C66: 16.4ft Endoscope Camera with Light for iPhone and Android, 1920P HD IP67 Waterproof Borescope with 8 Adjustable LED Lights, Semi-Rigid Snake Camera, 7.9mm Inspection Camera Black | D66: matrixcamp | E66: USB | F66: 25.987825 | G66: 40151.19 | H66: 1545 | I66: 526 | J66: 4.3 | K66: https://amazon.com/dp/B0CG46T9ZF | L66: =HYPERLINK(K66) -> https://amazon.com/dp/B0CG46T9ZF
A67: 11 | B67: B0C9JR3N4W | C67: Dual-Lens Endoscope Camera with Light, 1920P HD Borescope Tools with 8 Adjustable LED Lights, Endoscope with 16.4ft Semi-Rigid Snake Camera, IP67 Waterproof Inspection Borescope for iOS and Android | D67: kinpthy | E67: USB | F67: 35.99 | G67: 53985 | H67: 1500 | I67: 4574 | J67: 4.3 | K67: https://amazon.com/dp/B0C9JR3N4W | L67: =HYPERLINK(K67) -> https://amazon.com/dp/B0C9JR3N4W
A68: 12 | B68: B0CC27QRQ6 | C68: 1920P Snake Inspection Borescope, Pancellent Type C Endoscope, Scope Camera with 8 LED Lights for Android and iOS Smartphone, iPhone, iPad, Samsung (16.5 FT/5M) | D68: pancellent | E68: USB | F68: 21.822619 | G68: 31577.33 | H68: 1447 | I68: 1226 | J68: 4.5 | K68: https://amazon.com/dp/B0CC27QRQ6 | L68: =HYPERLINK(K68) -> https://amazon.com/dp/B0CC27QRQ6
... A106: 50 | B106: B07PBW52SF | C106: Oiiwak Endoscope Camera with Light, 5.5 mm Borescope, 4.3" IPS Screen HD Digital Snake Inspection Camera, IP67 Waterproof for Drain, Plumbing, Wall, Automotive- 3.5 m/11.5 ft | D106: oiiwak | E106: Portrait | F106: 50.048109 | G106: 17466.79 | H106: 349 | I106: 3482 | J106: 4.3 | K106: https://amazon.com/dp/B07PBW52SF | L106: =HYPERLINK(K106) -> https://amazon.com/dp/B07PBW52SF

Sheet Top 50 Summary
A1: Top 50 By Revenue Summary
B2: Avg Price | C2: Quantity/Mo | D2: Qty by % | E2: Revenue/Mo | F2: Revenue by %
A3: Articulation | B3: 134.60777 | C3: 8395 | D3: =C3/$C$9 -> 0.15920426 | E3: 1108536.7 | F3: =E3/$E$9 -> 0.36552859
A4: Handheld | B4: 77.827191 | C4: 6103 | D4: =C4/$C$9 -> 0.11573837 | E4: 325599.27 | F4: =E4/$E$9 -> 0.10736302
A5: Landscape | B5: 80.242864 | C5: 18348 | D5: =C5/$C$9 -> 0.34795471 | E5: 996505.9 | F5: =E5/$E$9 -> 0.32858759
A6: Portrait | B6: 50.048109 | C6: 349 | D6: =C6/$C$9 -> 0.0066184977 | E6: 17466.79 | F6: =E6/$E$9 -> 0.0057594947
A7: USB | B7: 30.285742 | C7: 17789 | D7: =C7/$C$9 -> 0.33735374 | E7: 507711.86 | F7: =E7/$E$9 -> 0.16741277
A8: Wireless | B8: 42.480585 | C8: 1747 | D8: =C8/$C$9 -> 0.033130417 | E8: 76874.38 | F8: =E8/$E$9 -> 0.025348537
A9: Total | B9: 79.895607 | C9: 52731 | D9: 1 | E9: 3032694.9 | F9: 1
A27: Top 50 By Unit Summary
B28: Avg Price | C28: Quantity/Mo | D28: Qty by % | E28: Revenue/Mo | F28: Revenue by %
A29: Articulation | B29: 133.22703 | C29: 7623 | D29: =C29/$C$35 -> 0.13749752 | E29: 1012457.6 | F29: =E29/$E$35 -> 0.34885551
A30: Handheld | B30: 53.604589 | C30: 6472 | D30: =C30/$C$35 -> 0.11673671 | E30: 305052.96 | F30: =E30/$E$35 -> 0.10510999
A31: Landscape | B31: 47.434856 | C31: 18848 | D31: =C31/$C$35 -> 0.33996501 | E31: 914957.48 | F31: =E31/$E$35 -> 0.31526058
A32: Portrait | B32: 50.048109 | C32: 349 | D32: =C32/$C$35 -> 0.0062949802 | E32: 17466.79 | F32: =E32/$E$35 -> 0.0060184111
A33: USB | B33: 28.81246 | C33: 20402 | D33: =C33/$C$35 -> 0.36799481 | E33: 575416.93 | F33: =E33/$E$35 -> 0.19826744
A34: Wireless | B34: 42.480585 | C34: 1747 | D34: =C34/$C$35 -> 0.031510976 | E34: 76874.38 | F34: =E34/$E$35 -> 0.026488074
A35: Total | B35: 55.424452 | C35: 55441 | D35: 1 | E35: 2902226.1 | F35: 1

Sheet DAXIONGMAO
A1: #VALUE!
A7: Rank by Revenue
A8: Product Name | B8: ASIN | C8: Avg Price | D8: Estimated 12mo Revenue | E8: Monthly Rev | F8: Estimated 12mo Units | G8: Monthly Units | H8: # of Reviews | I8: Tool Rating | J8: Column1 | K8: Link
A9: Endoscope Camera with Light, Borescope Camera with 4.3" IPS Screen, 1080P HD with 8 LED Lights, 16.4FT Semi-Rigid Cord Bore Scope, Tools for Men | B9: B0C3R381FC | C9: 37.149725 | D9: 1087298.2 | E9: 90608.18 | F9: 29268 | G9: 2439 | H9: 2494 | I9: 4.4 | J9: https://amazon.com/dp/B0C3R381FC | K9: =HYPERLINK(J9) -> https://amazon.com/dp/B0C3R381FC
A10: Endoscope Camera with Light, 1080P HD Borescope Tools with 8 Adjustable LED Lights, 4.3" Endoscope with 16.4ft Semi-Rigid Snake Camera, IP67 Waterproof Inspection Borescope, Gadgets for Men | B10: B0BXSMSS7M | C10: 38.009592 | D10: 759887.76 | E10: 63323.98 | F10: 19992 | G10: 1666 | H10: 1189 | I10: 4.4 | J10: https://amazon.com/dp/B0BXSMSS7M | K10: =HYPERLINK(J10) -> https://amazon.com/dp/B0BXSMSS7M
A11: Daxiongmao Borescope，Endoscope Camera with Light, 1080P HD Borescope Tools with 8 Adjustable LED Lights, Endoscope with 16.4ft Semi-Rigid Snake Camera, Gadgets for Men（2.4“） | B11: B0B8HKQFPD | C11: 25.904926 | D11: 125587.08 | E11: 10465.59 | F11: 4848 | G11: 404 | H11: 2492 | I11: 4.4 | J11: https://amazon.com/dp/B0B8HKQFPD | K11: =HYPERLINK(J11) -> https://amazon.com/dp/B0B8HKQFPD
A12: Daxiongmao Borescope, Endoscope Camera with Light, 1920 HD Industrial Endoscope Inspection Camera with Light, 4.3" Video Inspection Endoscope for Automotive Aircraft Mechanics Tools & Gifts for Men | B12: B0CW67ZYP1 | C12: 89.778462 | D12: 84032.64 | E12: 7002.72 | F12: 936 | G12: 78 | H12: 46 | I12: 4.7 | J12: https://amazon.com/dp/B0CW67ZYP1 | K12: =HYPERLINK(J12) -> https://amazon.com/dp/B0CW67ZYP1
A13: Endoscope Camera with Light, Borescope Camera with 4.3" IPS Screen, 1080P HD with 8 LED Lights, 16.4FT Semi-Rigid Cord Bore Scope, IP67 Waterproof Endoscope for Sewer, Tools for Men (Black) | B13: B0BYHMRHG1 | C13: 50.079138 | D13: 69710.16 | E13: 5809.18 | F13: 1392 | G13: 116 | H13: 160 | I13: 4.2 | J13: https://amazon.com/dp/B0BYHMRHG1 | K13: =HYPERLINK(J13) -> https://amazon.com/dp/B0BYHMRHG1
A14: Daxiongmao Borescope, Endoscope Camera with Light, IP67 Waterproof Endoscope, 1080 HD Inspection Endoscope, Snake Camera with 50FT Semi-Rigid Cord, Gadgets for Men(2.4") | B14: B0BX6H8Y27 | C14: 47.7 | D14: 40068 | E14: 3339 | F14: 840 | G14: 70 | H14: 161 | I14: 4.1 | J14: https://amazon.com/dp/B0BX6H8Y27 | K14: =HYPERLINK(J14) -> https://amazon.com/dp/B0BX6H8Y27
A15: Daxiongmao Borescope, Fits 0.22 "~0.3" Caliber Larger-Shooting Firearms Visual Barrel Inspection Tools, Gadgets for Men | B15: B0CW68KT2V | C15: 40.215 | D15: 18338.04 | E15: 1528.17 | F15: 456 | G15: 38 | H15: 39 | I15: 3.8 | J15: https://amazon.com/dp/B0CW68KT2V | K15: =HYPERLINK(J15) -> https://amazon.com/dp/B0CW68KT2V
A16: Endoscope Camera with Light, 5" IPS Screen Borescope,1920P HD Inspection Camera with Lights, IP67 Waterproof Flexible Cable for Automotive/Home/Wall/Pipe/Car (16.5FT) | B16: B0C2P62QN5 | C16: 85.945 | D16: 6188.04 | E16: 515.67 | F16: 72 | G16: 6 | H16: 29 | I16: 4.4 | J16: https://amazon.com/dp/B0C2P62QN5 | K16: =HYPERLINK(J16) -> https://amazon.com/dp/B0C2P62QN5
A17: Total | D17: =SUM(D9:D16) -> 2191109.9 | E17: =SUM(E9:E16) -> 182592.49
A20: Rank by Units
A21: Product Name | B21: ASIN | C21: Avg Price | D21: Estimated 12mo Revenue | E21: Monthly Rev | F21: Estimated 12mo Units | G21: Monthly Units | H21: # of Reviews | I21: Tool Rating | J21: Column1 | K21: Link
A22: Endoscope Camera with Light, Borescope Camera with 4.3" IPS Screen, 1080P HD with 8 LED Lights, 16.4FT Semi-Rigid Cord Bore Scope, Tools for Men | B22: B0C3R381FC | C22: 37.149725 | D22: 1087298.2 | E22: 90608.18 | F22: 29268 | G22: 2439 | H22: 2494 | I22: 4.4 | J22: https://amazon.com/dp/B0C3R381FC | K22: =HYPERLINK(J22) -> https://amazon.com/dp/B0C3R381FC
A23: Endoscope Camera with Light, 1080P HD Borescope Tools with 8 Adjustable LED Lights, 4.3" Endoscope with 16.4ft Semi-Rigid Snake Camera, IP67 Waterproof Inspection Borescope, Gadgets for Men | B23: B0BXSMSS7M | C23: 38.009592 | D23: 759887.76 | E23: 63323.98 | F23: 19992 | G23: 1666 | H23: 1189 | I23: 4.4 | J23: https://amazon.com/dp/B0BXSMSS7M | K23: =HYPERLINK(J23) -> https://amazon.com/dp/B0BXSMSS7M
A24: Daxiongmao Borescope，Endoscope Camera with Light, 1080P HD Borescope Tools with 8 Adjustable LED Lights, Endoscope with 16.4ft Semi-Rigid Snake Camera, Gadgets for Men（2.4“） | B24: B0B8HKQFPD | C24: 25.904926 | D24: 125587.08 | E24: 10465.59 | F24: 4848 | G24: 404 | H24: 2492 | I24: 4.4 | J24: https://amazon.com/dp/B0B8HKQFPD | K24: =HYPERLINK(J24) -> https://amazon.com/dp/B0B8HKQFPD
A25: Endoscope Camera with Light, Borescope Camera with 4.3" IPS Screen, 1080P HD with 8 LED Lights, 16.4FT Semi-Rigid Cord Bore Scope, IP67 Waterproof Endoscope for Sewer, Tools for Men (Black) | B25: B0BYHMRHG1 | C25: 50.079138 | D25: 69710.16 | E25: 5809.18 | F25: 1392 | G25: 116 | H25: 160 | I25: 4.2 | J25: https://amazon.com/dp/B0BYHMRHG1 | K25: =HYPERLINK(J25) -> https://amazon.com/dp/B0BYHMRHG1
A26: Daxiongmao Borescope, Endoscope Camera with Light, 1920 HD Industrial Endoscope Inspection Camera with Light, 4.3" Video Inspection Endoscope for Automotive Aircraft Mechanics Tools & Gifts for Men | B26: B0CW67ZYP1 | C26: 89.778462 | D26: 84032.64 | E26: 7002.72 | F26: 936 | G26: 78 | H26: 46 | I26: 4.7 | J26: https://amazon.com/dp/B0CW67ZYP1 | K26: =HYPERLINK(J26) -> https://amazon.com/dp/B0CW67ZYP1
A27: Daxiongmao Borescope, Endoscope Camera with Light, IP67 Waterproof Endoscope, 1080 HD Inspection Endoscope, Snake Camera with 50FT Semi-Rigid Cord, Gadgets for Men(2.4") | B27: B0BX6H8Y27 | C27: 47.7 | D27: 40068 | E27: 3339 | F27: 840 | G27: 70 | H27: 161 | I27: 4.1 | J27: https://amazon.com/dp/B0BX6H8Y27 | K27: =HYPERLINK(J27) -> https://amazon.com/dp/B0BX6H8Y27
A28: Daxiongmao Borescope, Fits 0.22 "~0.3" Caliber Larger-Shooting Firearms Visual Barrel Inspection Tools, Gadgets for Men | B28: B0CW68KT2V | C28: 40.215 | D28: 18338.04 | E28: 1528.17 | F28: 456 | G28: 38 | H28: 39 | I28: 3.8 | J28: https://amazon.com/dp/B0CW68KT2V | K28: =HYPERLINK(J28) -> https://amazon.com/dp/B0CW68KT2V
A29: Endoscope Camera with Light, 5" IPS Screen Borescope,1920P HD Inspection Camera with Lights, IP67 Waterproof Flexible Cable for Automotive/Home/Wall/Pipe/Car (16.5FT) | B29: B0C2P62QN5 | C29: 85.945 | D29: 6188.04 | E29: 515.67 | F29: 72 | G29: 6 | H29: 29 | I29: 4.4 | J29: https://amazon.com/dp/B0C2P62QN5 | K29: =HYPERLINK(J29) -> https://amazon.com/dp/B0C2P62QN5
A30: Total | F30: =SUM(Table43[Estimated 12mo Units]) -> 57804 | G30: =SUM(Table43[Monthly Units]) -> 4817

Sheet DEPSTECH
A1: #VALUE!
A7: Rank by Revenue
A8: Product Name | B8: ASIN | C8: Avg Price | D8: Estimated 12mo Revenue | E8: Monthly Rev | F8: Estimated 12mo Units | G8: Monthly Units | H8: # of Reviews | I8: Tool Rating | J8: Column1 | K8: Link
A9: DEPSTECH Dual Lens Industrial Endoscope, 1080P Digital Borescope Inspection Camera, 7.9mm IP67 Waterproof Camera, Sewer Camera with 4.3" LCD Screen,7 LED Lights,16.5FT Semi-Rigid Cable,32GB Card-Black | B9: B0928Q3T42 | C9: 63.776025 | D9: 2083180.1 | E9: 173598.34 | F9: 32664 | G9: 2722 | H9: 6096 | I9: 4.5 | J9: https://amazon.com/dp/B0928Q3T42 | K9: =HYPERLINK(J9) -> https://amazon.com/dp/B0928Q3T42
A10: Triple Lens Sewer Inspection Camera with 50FT Semi-Rigid Cable, DEPSTECH 5"IPS Screen Endoscope Camera with Lights, 1080P Industrial Borescope, Split Screen, Waterproof Drain Pipe Camera,Carrying Case | B10: B0BS1CFFH8 | C10: 129.94307 | D10: 1746434.9 | E10: 145536.24 | F10: 13440 | G10: 1120 | H10: 1784 | I10: 4.4 | J10: https://amazon.com/dp/B0BS1CFFH8 | K10: =HYPERLINK(J10) -> https://amazon.com/dp/B0BS1CFFH8
A11: Dual-Lens Endoscope Camera with Light, DEPSTECH 1080P HD Borescope with 5" IPS Screen, 16.5FT Flexible Sewer Camera, IP67 Waterproof Plumbing Snake Camera, Cool Gadgets for Men, Women | B11: B0CT2CX59S | C11: 68.750387 | D11: 831604.68 | E11: 69300.39 | F11: 12096 | G11: 1008 | H11: 485 | I11: 4.6 | J11: https://amazon.com/dp/B0CT2CX59S | K11: =HYPERLINK(J11) -> https://amazon.com/dp/B0CT2CX59S
A12: DEPSTECH Dual Lens Wireless Endoscope, 1080P Scope Snake Camera with 7 LED Lights,0.31In Lens Video HD Inspection Camera,IP67 Waterproof Borescope,16.5FT Cable for Android & iOS Phone or Tablet-Yellow | B12: B08NJ8627V | C12: 54.972592 | D12: 646477.68 | E12: 53873.14 | F12: 11760 | G12: 980 | H12: 2494 | I12: 4.4 | J12: https://amazon.com/dp/B08NJ8627V | K12: =HYPERLINK(J12) -> https://amazon.com/dp/B08NJ8627V
A13: DEPSTECH 210° Two-Way Articulating Borescope, 0.24in Ultra-Slim Endoscope Camera with Lights, 4.5” IPS Screen, 5ft Waterproof Flexible Snake Tube, Industrial Inspection Camera for Automotive Mechanics | B13: B0DBZ6Q4YH | C13: 121.44505 | D13: 632485.8 | E13: 52707.15 | F13: 5208 | G13: 434 | H13: 208 | I13: 4.5 | J13: https://amazon.com/dp/B0DBZ6Q4YH | K13: =HYPERLINK(J13) -> https://amazon.com/dp/B0DBZ6Q4YH
A14: 50FT Endoscope Camera with Lights, DEPSTECH 1080P Dual Lens Borescope Inspection Camera with Split Screen, 5" IPS Screen,IP67 Waterproof Sewer Camera Cable,7.9mm Scope Camera for Drain Pipe Automotive | B14: B0BYF9J7V9 | C14: 120.05338 | D14: 383210.4 | E14: 31934.2 | F14: 3192 | G14: 266 | H14: 1469 | I14: 4.5 | J14: https://amazon.com/dp/B0BYF9J7V9 | K14: =HYPERLINK(J14) -> https://amazon.com/dp/B0BYF9J7V9
A15: DEPSTECH 50FT Triple Lens Sewer Borescope with 5" IPS Screen, 1080P Endoscope Camera with Light, Flexible Snake Inspection Camera for Wall, Plumbing, Automotive Engine Inspect | B15: B0DD351NSB | C15: 129.79962 | D15: 369150.12 | E15: 30762.51 | F15: 2844 | G15: 237 | H15: 144 | I15: 4.3 | J15: https://amazon.com/dp/B0DD351NSB | K15: =HYPERLINK(J15) -> https://amazon.com/dp/B0DD351NSB
A16: DEPSTECH Dual Lens Borescope, HD Endoscope Camera with Light, 4.3'' IPS Screen Inspection Camera, IP67 Waterproof Drain Pipe Camera, 16.5ft Semi-Rigid Snake Camera Cable for Car Wall Plumbing HVAC | B16: B0DD47VS7S | C16: 49.985962 | D16: 349101.96 | E16: 29091.83 | F16: 6984 | G16: 582 | H16: 169 | I16: 4.5 | J16: https://amazon.com/dp/B0DD47VS7S | K16: =HYPERLINK(J16) -> https://amazon.com/dp/B0DD47VS7S
A17: DEPSTECH Endoscope, 7'' IPS Screen Borescope Camera with Light, Triple-Lens Inspection Camera with Sound Recording, 1080P HD 7.9 mm Snake Camera, 16.5ft Gooseneck Camera for Automotive Wall Pipe HVAC | B17: B0BVML78W1 | C17: 239.97707 | D17: 264934.68 | E17: 22077.89 | F17: 1104 | G17: 92 | H17: 154 | I17: 4.6 | J17: https://amazon.com/dp/B0BVML78W1 | K17: =HYPERLINK(J17) -> https://amazon.com/dp/B0BVML78W1
A18: 7'' IPS Endoscope Camera with Lights, DEPSTECH 1080P Triple-Lens Digital Borescope Tool, Inspection Camera with Split Screen, Sound Recording, 16.5ft IP67 Snake Drain Camera Cable, 180° Rotation View | B18: B0CT5L1H9B | C18: 152.61147 | D18: 236242.56 | E18: 19686.88 | F18: 1548 | G18: 129 | H18: 143 | I18: 4.6 | J18: https://amazon.com/dp/B0CT5L1H9B | K18: =HYPERLINK(J18) -> https://amazon.com/dp/B0CT5L1H9B
A19: 50FT Triple Lens Sewer Inspection Camera, DEPSTECH Upgraded 5'' IPS Endoscope Camera with Light, 1080P HD Borescope with Split Screen, Waterproof Drain Pipe Plumbing Camera, Cool Tech Gadgets for Men | B19: B0CMTX8ZM6 | C19: 132.9497 | D19: 161135.04 | E19: 13427.92 | F19: 1212 | G19: 101 | H19: 181 | I19: 4.3 | J19: https://amazon.com/dp/B0CMTX8ZM6 | K19: =HYPERLINK(J19) -> https://amazon.com/dp/B0CMTX8ZM6
A20: Triple Lens Industrial Endoscope Camera with Lights, DEPSTECH 1080P Borescope with Split Screen, 5" IPS Screen Sewer Inspection Camera, IP67 Waterproof, Helpful Tool for Wall Duct Drain Pipe-4.92ft | B20: B0BYZGT1LV | C20: 99.626429 | D20: 133897.92 | E20: 11158.16 | F20: 1344 | G20: 112 | H20: 1784 | I20: 4.4 | J20: https://amazon.com/dp/B0BYZGT1LV | K20: =HYPERLINK(J20) -> https://amazon.com/dp/B0BYZGT1LV
... A36: DEPSTECH Wireless Endoscope Hook Magnet Side View Mirror Set, Including 30 45 60 Degree Mirror for Depstech WF010 Borescope- Black | B36: B075Q9TBJM | C36: 16.99 | D36: 0 | E36: 0 | F36: 0 | G36: 0 | H36: 2009 | I36: 4.2 | J36: https://amazon.com/dp/B075Q9TBJM | K36: =HYPERLINK(J36) -> https://amazon.com/dp/B075Q9TBJM
A37: Total | D37: =SUM(D9:D36) -> 8602301.9 | E37: =SUM(E9:E36) -> 716858.49
A40: Rank by Units
A41: Product Name | B41: ASIN | C41: Avg Price | D41: Estimated 12mo Revenue | E41: Monthly Rev | F41: Estimated 12mo Units | G41: Monthly Units | H41: # of Reviews | I41: Tool Rating | J41: Column1 | K41: Link
A42: DEPSTECH Dual Lens Industrial Endoscope, 1080P Digital Borescope Inspection Camera, 7.9mm IP67 Waterproof Camera, Sewer Camera with 4.3" LCD Screen,7 LED Lights,16.5FT Semi-Rigid Cable,32GB Card-Black | B42: B0928Q3T42 | C42: 63.776025 | D42: 2083180.1 | E42: 173598.34 | F42: 32664 | G42: 2722 | H42: 6096 | I42: 4.5 | J42: https://amazon.com/dp/B0928Q3T42 | K42: =HYPERLINK(J42) -> https://amazon.com/dp/B0928Q3T42
A43: Triple Lens Sewer Inspection Camera with 50FT Semi-Rigid Cable, DEPSTECH 5"IPS Screen Endoscope Camera with Lights, 1080P Industrial Borescope, Split Screen, Waterproof Drain Pipe Camera,Carrying Case | B43: B0BS1CFFH8 | C43: 129.94307 | D43: 1746434.9 | E43: 145536.24 | F43: 13440 | G43: 1120 | H43: 1784 | I43: 4.4 | J43: https://amazon.com/dp/B0BS1CFFH8 | K43: =HYPERLINK(J43) -> https://amazon.com/dp/B0BS1CFFH8
A44: Dual-Lens Endoscope Camera with Light, DEPSTECH 1080P HD Borescope with 5" IPS Screen, 16.5FT Flexible Sewer Camera, IP67 Waterproof Plumbing Snake Camera, Cool Gadgets for Men, Women | B44: B0CT2CX59S | C44: 68.750387 | D44: 831604.68 | E44: 69300.39 | F44: 12096 | G44: 1008 | H44: 485 | I44: 4.6 | J44: https://amazon.com/dp/B0CT2CX59S | K44: =HYPERLINK(J44) -> https://amazon.com/dp/B0CT2CX59S
A45: DEPSTECH Dual Lens Wireless Endoscope, 1080P Scope Snake Camera with 7 LED Lights,0.31In Lens Video HD Inspection Camera,IP67 Waterproof Borescope,16.5FT Cable for Android & iOS Phone or Tablet-Yellow | B45: B08NJ8627V | C45: 54.972592 | D45: 646477.68 | E45: 53873.14 | F45: 11760 | G45: 980 | H45: 2494 | I45: 4.4 | J45: https://amazon.com/dp/B08NJ8627V | K45: =HYPERLINK(J45) -> https://amazon.com/dp/B08NJ8627V
A46: DEPSTECH Dual Lens Borescope, HD Endoscope Camera with Light, 4.3'' IPS Screen Inspection Camera, IP67 Waterproof Drain Pipe Camera, 16.5ft Semi-Rigid Snake Camera Cable for Car Wall Plumbing HVAC | B46: B0DD47VS7S | C46: 49.985962 | D46: 349101.96 | E46: 29091.83 | F46: 6984 | G46: 582 | H46: 169 | I46: 4.5 | J46: https://amazon.com/dp/B0DD47VS7S | K46: =HYPERLINK(J46) -> https://amazon.com/dp/B0DD47VS7S
A47: DEPSTECH 210° Two-Way Articulating Borescope, 0.24in Ultra-Slim Endoscope Camera with Lights, 4.5” IPS Screen, 5ft Waterproof Flexible Snake Tube, Industrial Inspection Camera for Automotive Mechanics | B47: B0DBZ6Q4YH | C47: 121.44505 | D47: 632485.8 | E47: 52707.15 | F47: 5208 | G47: 434 | H47: 208 | I47: 4.5 | J47: https://amazon.com/dp/B0DBZ6Q4YH | K47: =HYPERLINK(J47) -> https://amazon.com/dp/B0DBZ6Q4YH
A48: 50FT Endoscope Camera with Lights, DEPSTECH 1080P Dual Lens Borescope Inspection Camera with Split Screen, 5" IPS Screen,IP67 Waterproof Sewer Camera Cable,7.9mm Scope Camera for Drain Pipe Automotive | B48: B0BYF9J7V9 | C48: 120.05338 | D48: 383210.4 | E48: 31934.2 | F48: 3192 | G48: 266 | H48: 1469 | I48: 4.5 | J48: https://amazon.com/dp/B0BYF9J7V9 | K48: =HYPERLINK(J48) -> https://amazon.com/dp/B0BYF9J7V9
A49: DEPSTECH 50FT Triple Lens Sewer Borescope with 5" IPS Screen, 1080P Endoscope Camera with Light, Flexible Snake Inspection Camera for Wall, Plumbing, Automotive Engine Inspect | B49: B0DD351NSB | C49: 129.79962 | D49: 369150.12 | E49: 30762.51 | F49: 2844 | G49: 237 | H49: 144 | I49: 4.3 | J49: https://amazon.com/dp/B0DD351NSB | K49: =HYPERLINK(J49) -> https://amazon.com/dp/B0DD351NSB
A50: DEPSTECH Original Endoscope Case, Wireless Borescope Carrying Bag WiFi & USB Scope Cameras, Upgraded Large-Capacity Hardshell Case, Compatible with 4.3" Inspection Camera DS300, Black | B50: B076D86Z7S | C50: 22.012207 | D50: 58640.52 | E50: 4886.71 | F50: 2664 | G50: 222 | H50: 2919 | I50: 4.6 | J50: https://amazon.com/dp/B076D86Z7S | K50: =HYPERLINK(J50) -> https://amazon.com/dp/B076D86Z7S
A51: DEPSTECH Industrial Borescope Tool & 4.3" IPS Screen, Bluart 3.0 Tech, HD Digital Endoscope Camera Lights, IP67 Inspection Camera, 16.5FT Semi-Rigid Drain Snake Cable, Cool Gadget Gift, Mechanic Tool | B51: B0CQG1RGL6 | C51: 40.063264 | D51: 92786.52 | E51: 7732.21 | F51: 2316 | G51: 193 | H51: 439 | I51: 4.6 | J51: https://amazon.com/dp/B0CQG1RGL6 | K51: =HYPERLINK(J51) -> https://amazon.com/dp/B0CQG1RGL6
A52: DEPSTECH Wireless Endoscope, IP67 Waterproof WiFi Borescope Inspection 2.0 Megapixels HD Snake Camera for Android and iOS Smartphone, iPhone, Samsung, Tablet -Blue(11.5FT) | B52: B09GJZG912 | C52: 37.963088 | D52: 61955.76 | E52: 5162.98 | F52: 1632 | G52: 136 | H52: 21270 | I52: 4.2 | J52: https://amazon.com/dp/B09GJZG912 | K52: =HYPERLINK(J52) -> https://amazon.com/dp/B09GJZG912
A53: DEPSTECH Dual Lens Industrial Endoscope, 1080P Digital Borescope Inspection Camera, 7.9mm IP67 Waterproof, Sewer Camera with 4.3" LCD Screen, 7 LED Lights, 16.5FT Semi-Rigid Cable, 32GB Card - Orange | B53: B09DKKJGS7 | C53: 66.420519 | D53: 107601.24 | E53: 8966.77 | F53: 1620 | G53: 135 | H53: 6096 | I53: 4.5 | J53: https://amazon.com/dp/B09DKKJGS7 | K53: =HYPERLINK(J53) -> https://amazon.com/dp/B09DKKJGS7
... A69: DEPSTECH Wireless Endoscope Hook Magnet Side View Mirror Set, Including 30 45 60 Degree Mirror for Depstech WF010 Borescope- Black | B69: B075Q9TBJM | C69: 16.99 | D69: 0 | E69: 0 | F69: 0 | G69: 0 | H69: 2009 | I69: 4.2 | J69: https://amazon.com/dp/B075Q9TBJM | K69: =HYPERLINK(J69) -> https://amazon.com/dp/B075Q9TBJM
A70: Total | F70: =SUM(Table4316[Estimated 12mo Units]) -> 107412 | G70: =SUM(Table4316[Monthly Units]) -> 8951

Sheet DZXtoz
A1: #VALUE!
A7: Rank by Revenue
A8: Product Name | B8: ASIN | C8: Avg Price | D8: Estimated 12mo Revenue | E8: Monthly Rev | F8: Estimated 12mo Units | G8: Monthly Units | H8: # of Reviews | I8: Tool Rating | J8: Column1 | K8: Link
A9: Two-Way Articulating Borescope, DXZtoz Industrial Endoscope with 0.33in Articulated Snake Camera, Video Inspection Scope with Light for Automotive Aircraft Mechanics- 5.5FT | B9: B0B28HRSBP | C9: 139.41909 | D9: 2926127.9 | E9: 243843.99 | F9: 20988 | G9: 1749 | H9: 1053 | I9: 4.6 | J9: https://amazon.com/dp/B0B28HRSBP | K9: =HYPERLINK(J9) -> https://amazon.com/dp/B0B28HRSBP
A10: 3.9mm Articulating Borescope, DXZtoz Professional Super Thin Endoscope Inspection Camera with Turnable Snake Camera, Flexible Gooseneck Fiber Optic Scope with Light, Cool Gadgets for Men- 3.3FT | B10: B0CJ8TBWG8 | C10: 219.99655 | D10: 229676.4 | E10: 19139.7 | F10: 1044 | G10: 87 | H10: 46 | I10: 3.9 | J10: https://amazon.com/dp/B0CJ8TBWG8 | K10: =HYPERLINK(J10) -> https://amazon.com/dp/B0CJ8TBWG8
A11: DXZtoz Original Endoscope Case, Borescope Carrying Bag for NTS500B 5inch Inspection Camera, Upgraded Large-Capacity Compatible for 50FT or Less Than 50FT Endoscopes, Black | B11: B0BFCMW8KS | C11: 16.99 | D11: 0 | E11: 0 | F11: 0 | G11: 0 | H11: 5 | I11: 5 | J11: https://amazon.com/dp/B0BFCMW8KS | K11: =HYPERLINK(J11) -> https://amazon.com/dp/B0BFCMW8KS
A12: Total | D12: =SUM(D9:D11) -> 3155804.3 | E12: =SUM(E9:E11) -> 262983.69
A15: Rank by Units
A16: Product Name | B16: ASIN | C16: Avg Price | D16: Estimated 12mo Revenue | E16: Monthly Rev | F16: Estimated 12mo Units | G16: Monthly Units | H16: # of Reviews | I16: Tool Rating | J16: Column1 | K16: Link
A17: Two-Way Articulating Borescope, DXZtoz Industrial Endoscope with 0.33in Articulated Snake Camera, Video Inspection Scope with Light for Automotive Aircraft Mechanics- 5.5FT | B17: B0B28HRSBP | C17: 139.41909 | D17: 2926127.9 | E17: 243843.99 | F17: 20988 | G17: 1749 | H17: 1053 | I17: 4.6 | J17: https://amazon.com/dp/B0B28HRSBP | K17: =HYPERLINK(J17) -> https://amazon.com/dp/B0B28HRSBP
A18: 3.9mm Articulating Borescope, DXZtoz Professional Super Thin Endoscope Inspection Camera with Turnable Snake Camera, Flexible Gooseneck Fiber Optic Scope with Light, Cool Gadgets for Men- 3.3FT | B18: B0CJ8TBWG8 | C18: 219.99655 | D18: 229676.4 | E18: 19139.7 | F18: 1044 | G18: 87 | H18: 46 | I18: 3.9 | J18: https://amazon.com/dp/B0CJ8TBWG8 | K18: =HYPERLINK(J18) -> https://amazon.com/dp/B0CJ8TBWG8
A19: DXZtoz Original Endoscope Case, Borescope Carrying Bag for NTS500B 5inch Inspection Camera, Upgraded Large-Capacity Compatible for 50FT or Less Than 50FT Endoscopes, Black | B19: B0BFCMW8KS | C19: 16.99 | D19: 0 | E19: 0 | F19: 0 | G19: 0 | H19: 5 | I19: 5 | J19: https://amazon.com/dp/B0BFCMW8KS | K19: =HYPERLINK(J19) -> https://amazon.com/dp/B0BFCMW8KS
A20: Total | F20: =SUM(DZXtoz!F17:F19) -> 22032 | G20: =SUM(DZXtoz!G17:G19) -> 1836

Sheet Hijoy
A1: #VALUE!
A7: Rank by Revenue
A8: Product Name | B8: ASIN | C8: Avg Price | D8: Estimated 12mo Revenue | E8: Monthly Rev | F8: Estimated 12mo Units | G8: Monthly Units | H8: # of Reviews | I8: Tool Rating | J8: Column1 | K8: Link
A9: Hijoy Articulating Borescope Camera with Light - 5'' 1080P HD Display Industrial Endoscope Inspection Camera 5.5FT Snake Camera for Automotive HVAC and Industrial Mechanics | B9: B0D59Y7B2D | C9: 150.79807 | D9: 908407.56 | E9: 75700.63 | F9: 6024 | G9: 502 | H9: 70 | I9: 4.7 | J9: https://amazon.com/dp/B0D59Y7B2D | K9: =HYPERLINK(J9) -> https://amazon.com/dp/B0D59Y7B2D
A10: Endoscope Camera with Light, Hijoy Two-Way Articulation Borescope, 0.33in Articulating Inspection Scope with Light, Perfect for Automotive & Aircraft Mechanics, 5.5FT | B10: B0D3XDGN6M | C10: 129.83585 | D10: 641908.44 | E10: 53492.37 | F10: 4944 | G10: 412 | H10: 227 | I10: 4.7 | J10: https://amazon.com/dp/B0D3XDGN6M | K10: =HYPERLINK(J10) -> https://amazon.com/dp/B0D3XDGN6M
A11: Total | D11: =SUM(D9:D10) -> 1550316 | E11: =SUM(E9:E10) -> 129193
A14: Rank by Units
A15: Product Name | B15: ASIN | C15: Avg Price | D15: Estimated 12mo Revenue | E15: Monthly Rev | F15: Estimated 12mo Units | G15: Monthly Units | H15: # of Reviews | I15: Tool Rating | J15: Column1 | K15: Link
A16: Hijoy Articulating Borescope Camera with Light - 5'' 1080P HD Display Industrial Endoscope Inspection Camera 5.5FT Snake Camera for Automotive HVAC and Industrial Mechanics | B16: B0D59Y7B2D | C16: 150.79807 | D16: 908407.56 | E16: 75700.63 | F16: 6024 | G16: 502 | H16: 70 | I16: 4.7 | J16: https://amazon.com/dp/B0D59Y7B2D | K16: =HYPERLINK(J16) -> https://amazon.com/dp/B0D59Y7B2D
A17: Endoscope Camera with Light, Hijoy Two-Way Articulation Borescope, 0.33in Articulating Inspection Scope with Light, Perfect for Automotive & Aircraft Mechanics, 5.5FT | B17: B0D3XDGN6M | C17: 129.83585 | D17: 641908.44 | E17: 53492.37 | F17: 4944 | G17: 412 | H17: 227 | I17: 4.7 | J17: https://amazon.com/dp/B0D3XDGN6M | K17: =HYPERLINK(J17) -> https://amazon.com/dp/B0D3XDGN6M
A18: Total | F18: =SUM(Hijoy!F16:F17) -> 10968 | G18: =SUM(Hijoy!G16:G17) -> 914

Sheet KAIWEETS
A1: #VALUE!
A7: Rank by Revenue
A8: Product Name | B8: ASIN | C8: Avg Price | D8: Estimated 12mo Revenue | E8: Monthly Rev | F8: Estimated 12mo Units | G8: Monthly Units | H8: # of Reviews | I8: Tool Rating | J8: Column1 | K8: Link
A9: Two-Way Articulating Borescope Camera with Light, KAIWEETS 0.33in Industrial Endoscope Camera with Light, 5FT Flexible Snake Inspection Scope for Automotive and Aircraft Mechanics | B9: B0D9M3Q7FK | C9: 119.98787 | D9: 1209477.7 | E9: 100789.81 | F9: 10080 | G9: 840 | H9: 152 | I9: 4.3 | J9: https://amazon.com/dp/B0D9M3Q7FK | K9: =HYPERLINK(J9) -> https://amazon.com/dp/B0D9M3Q7FK

Sheet KINPTHY
A1: #VALUE!
A7: Rank by Revenue
A8: Product Name | B8: ASIN | C8: Avg Price | D8: Estimated 12mo Revenue | E8: Monthly Rev | F8: Estimated 12mo Units | G8: Monthly Units | H8: # of Reviews | I8: Tool Rating | J8: Column1 | K8: Link
A9: Endoscope Camera with Light, 1920P HD Borescope Tools with 8 Adjustable LED Lights, Endoscope with 16.4ft Semi-Rigid Snake Camera, IP67 Waterproof Inspection Borescope for iOS and Android-16.4ft | B9: B0C4V5LWWL | C9: 25.99 | D9: 1403460 | E9: 116955 | F9: 54000 | G9: 4500 | H9: 1548 | I9: 4.3 | J9: https://amazon.com/dp/B0C4V5LWWL | K9: =HYPERLINK(J9) -> https://amazon.com/dp/B0C4V5LWWL
A10: Dual-Lens Endoscope Camera with Light, 1920P HD Borescope Tools with 8 Adjustable LED Lights, Endoscope with 16.4ft Semi-Rigid Snake Camera, IP67 Waterproof Inspection Borescope for iOS and Android | B10: B0C9JR3N4W | C10: 35.99 | D10: 647820 | E10: 53985 | F10: 18000 | G10: 1500 | H10: 4574 | I10: 4.3 | J10: https://amazon.com/dp/B0C9JR3N4W | K10: =HYPERLINK(J10) -> https://amazon.com/dp/B0C9JR3N4W
A11: Endoscope Camera with Light, 1920P HD Borescope Tools with 8 Adjustable LED Lights, Endoscope with 32.8ft Semi-Rigid Snake Camera, IP67 Waterproof Inspection Borescope for iOS and Android-32.8ft | B11: B0BF64PP4F | C11: 35.99 | D11: 64782 | E11: 5398.5 | F11: 1800 | G11: 150 | H11: 321 | I11: 4.7 | J11: https://amazon.com/dp/B0BF64PP4F | K11: =HYPERLINK(J11) -> https://amazon.com/dp/B0BF64PP4F
A12: Endoscope Camera with Light, 1920P HD Borescope Tools with 9 Adjustable LED Lights, Endoscope with 16.4ft Semi-Rigid Snake Camera, 7.9mm IP67 Waterproof Inspection for iOS and Android | B12: B0C4V4FJC8 | C12: 35.99 | D12: 0 | E12: 0 | F12: 0 | G12: 0 | H12: 4578 | I12: 4.3 | J12: https://amazon.com/dp/B0C4V4FJC8 | K12: =HYPERLINK(J12) -> https://amazon.com/dp/B0C4V4FJC8
A13: Endoscope Camera with Light, Two-Way Articulating Borescope, 1080P HD Handheld Boroscope with 8 Adjustable LED Lights, IP67 Waterproof Automotive Borescope, Semi-Rigid Snake Inspection Camera(3.28FT) | B13: B0CBCBSYDG | C13: 79.99 | D13: 0 | E13: 0 | F13: 0 | G13: 0 | H13: 578 | I13: 4.5 | J13: https://amazon.com/dp/B0CBCBSYDG | K13: =HYPERLINK(J13) -> https://amazon.com/dp/B0CBCBSYDG
A14: Total | D14: =SUM(D9:D13) -> 2116062 | E14: =SUM(E9:E13) -> 176338.5
A17: Rank by Units
A18: Product Name | B18: ASIN | C18: Avg Price | D18: Estimated 12mo Revenue | E18: Monthly Rev | F18: Estimated 12mo Units | G18: Monthly Units | H18: # of Reviews | I18: Tool Rating | J18: Column1 | K18: Link
A19: Endoscope Camera with Light, 1920P HD Borescope Tools with 8 Adjustable LED Lights, Endoscope with 16.4ft Semi-Rigid Snake Camera, IP67 Waterproof Inspection Borescope for iOS and Android-16.4ft | B19: B0C4V5LWWL | C19: 25.99 | D19: 1403460 | E19: 116955 | F19: 54000 | G19: 4500 | H19: 1548 | I19: 4.3 | J19: https://amazon.com/dp/B0C4V5LWWL | K19: =HYPERLINK(J19) -> https://amazon.com/dp/B0C4V5LWWL
A20: Dual-Lens Endoscope Camera with Light, 1920P HD Borescope Tools with 8 Adjustable LED Lights, Endoscope with 16.4ft Semi-Rigid Snake Camera, IP67 Waterproof Inspection Borescope for iOS and Android | B20: B0C9JR3N4W | C20: 35.99 | D20: 647820 | E20: 53985 | F20: 18000 | G20: 1500 | H20: 4574 | I20: 4.3 | J20: https://amazon.com/dp/B0C9JR3N4W | K20: =HYPERLINK(J20) -> https://amazon.com/dp/B0C9JR3N4W
A21: Endoscope Camera with Light, 1920P HD Borescope Tools with 8 Adjustable LED Lights, Endoscope with 32.8ft Semi-Rigid Snake Camera, IP67 Waterproof Inspection Borescope for iOS and Android-32.8ft | B21: B0BF64PP4F | C21: 35.99 | D21: 64782 | E21: 5398.5 | F21: 1800 | G21: 150 | H21: 321 | I21: 4.7 | J21: https://amazon.com/dp/B0BF64PP4F | K21: =HYPERLINK(J21) -> https://amazon.com/dp/B0BF64PP4F
A22: Endoscope Camera with Light, 1920P HD Borescope Tools with 9 Adjustable LED Lights, Endoscope with 16.4ft Semi-Rigid Snake Camera, 7.9mm IP67 Waterproof Inspection for iOS and Android | B22: B0C4V4FJC8 | C22: 35.99 | D22: 0 | E22: 0 | F22: 0 | G22: 0 | H22: 4578 | I22: 4.3 | J22: https://amazon.com/dp/B0C4V4FJC8 | K22: =HYPERLINK(J22) -> https://amazon.com/dp/B0C4V4FJC8
A23: Endoscope Camera with Light, Two-Way Articulating Borescope, 1080P HD Handheld Boroscope with 8 Adjustable LED Lights, IP67 Waterproof Automotive Borescope, Semi-Rigid Snake Inspection Camera(3.28FT) | B23: B0CBCBSYDG | C23: 79.99 | D23: 0 | E23: 0 | F23: 0 | G23: 0 | H23: 578 | I23: 4.5 | J23: https://amazon.com/dp/B0CBCBSYDG | K23: =HYPERLINK(J23) -> https://amazon.com/dp/B0CBCBSYDG
A24: Total | F24: =SUM(Table431618[Estimated 12mo Units]) -> 73800 | G24: =SUM(Table431618[Monthly Units]) -> 6150

Sheet MugEasy
A1: #VALUE!
A7: Rank by Revenue
A8: Product Name | B8: ASIN | C8: Avg Price | D8: Estimated 12mo Revenue | E8: Monthly Rev | F8: Estimated 12mo Units | G8: Monthly Units | H8: # of Reviews | I8: Tool Rating | J8: Column1 | K8: Link
A9: Endoscope Camera with Light, Inspection Borescope Camera with 4.3" IPS Screen, 1920P HD with 8 LED Lights, 16.4FT Semi-Rigid Cord Bore Scope, IP67 Waterproof Endoscope for Sewer, Tools(Orange) | B9: B0CFF8Z1NF | C9: 41.444117 | D9: 1558133 | E9: 129844.42 | F9: 37596 | G9: 3133 | H9: 989 | I9: 4.6 | J9: https://amazon.com/dp/B0CFF8Z1NF | K9: =HYPERLINK(J9) -> https://amazon.com/dp/B0CFF8Z1NF
A10: Endoscope Camera with Light, Inspection Borescope Camera with 4.3" IPS Screen, 1920P HD with 8 LED Lights, 16.4FT Semi-Rigid Cord Bore Scope, IP67 Waterproof Endoscope for Sewer, Tools(Green) | B10: B0CXHYT8H8 | C10: 36.379925 | D10: 582369.84 | E10: 48530.82 | F10: 16008 | G10: 1334 | H10: 989 | I10: 4.6 | J10: https://amazon.com/dp/B0CXHYT8H8 | K10: =HYPERLINK(J10) -> https://amazon.com/dp/B0CXHYT8H8
A11: Endoscope Camera with Light, 1920P HD Bore Scope Borescope with 8 Lights, Waterproof 16.4FT Semi-Rigid Cord for Pipe Inspection, Industrial Endoscope for Phones(Black) | B11: B0C4FBM6GV | C11: 28.584173 | D11: 130686.84 | E11: 10890.57 | F11: 4572 | G11: 381 | H11: 922 | I11: 4.4 | J11: https://amazon.com/dp/B0C4FBM6GV | K11: =HYPERLINK(J11) -> https://amazon.com/dp/B0C4FBM6GV
A12: Endoscope Camera with Light, 1920P HD Bore Scope Borescope with 8 Lights, Waterproof 16.4FT Semi-Rigid Cord for Pipe Inspection, Industrial Endoscope for Phones(Blue) | B12: B0C5M8SRQ8 | C12: 28.715556 | D12: 3101.28 | E12: 258.44 | F12: 108 | G12: 9 | H12: 921 | I12: 4.3 | J12: https://amazon.com/dp/B0C5M8SRQ8 | K12: =HYPERLINK(J12) -> https://amazon.com/dp/B0C5M8SRQ8
A13: MugEasy Endoscope Hook Magnet Side View Mirror Kit Tools for MugEasy Endoscope Camera with Light - Black (6 pcs) | B13: B0D9D8TWZB | C13: 16.864 | D13: 2023.68 | E13: 168.64 | F13: 120 | G13: 10 | H13: 3 | I13: 3.1 | J13: https://amazon.com/dp/B0D9D8TWZB | K13: =HYPERLINK(J13) -> https://amazon.com/dp/B0D9D8TWZB
A14: Endoscope Camera with Light, 1920P HD Bore Scope Borescope with 8 Lights, Waterproof 16.4FT Semi-Rigid Cord for Pipe Inspection, Industrial Endoscope for Phones(Yellow) | B14: B0C5M7ZH65 | C14: 29.99 | D14: 0 | E14: 0 | F14: 0 | G14: 0 | H14: 921 | I14: 4.3 | J14: https://amazon.com/dp/B0C5M7ZH65 | K14: =HYPERLINK(J14) -> https://amazon.com/dp/B0C5M7ZH65
A15: Total | D15: =SUM(D9:D14) -> 2276314.7 | E15: =SUM(E9:E14) -> 189692.89
A18: Rank by Units
A19: Product Name | B19: ASIN | C19: Avg Price | D19: Estimated 12mo Revenue | E19: Monthly Rev | F19: Estimated 12mo Units | G19: Monthly Units | H19: # of Reviews | I19: Tool Rating | J19: Column1 | K19: Link
A20: Endoscope Camera with Light, Inspection Borescope Camera with 4.3" IPS Screen, 1920P HD with 8 LED Lights, 16.4FT Semi-Rigid Cord Bore Scope, IP67 Waterproof Endoscope for Sewer, Tools(Orange) | B20: B0CFF8Z1NF | C20: 41.444117 | D20: 1558133 | E20: 129844.42 | F20: 37596 | G20: 3133 | H20: 989 | I20: 4.6 | J20: https://amazon.com/dp/B0CFF8Z1NF | K20: =HYPERLINK(J20) -> https://amazon.com/dp/B0CFF8Z1NF
A21: Endoscope Camera with Light, Inspection Borescope Camera with 4.3" IPS Screen, 1920P HD with 8 LED Lights, 16.4FT Semi-Rigid Cord Bore Scope, IP67 Waterproof Endoscope for Sewer, Tools(Green) | B21: B0CXHYT8H8 | C21: 36.379925 | D21: 582369.84 | E21: 48530.82 | F21: 16008 | G21: 1334 | H21: 989 | I21: 4.6 | J21: https://amazon.com/dp/B0CXHYT8H8 | K21: =HYPERLINK(J21) -> https://amazon.com/dp/B0CXHYT8H8
A22: Endoscope Camera with Light, 1920P HD Bore Scope Borescope with 8 Lights, Waterproof 16.4FT Semi-Rigid Cord for Pipe Inspection, Industrial Endoscope for Phones(Black) | B22: B0C4FBM6GV | C22: 28.584173 | D22: 130686.84 | E22: 10890.57 | F22: 4572 | G22: 381 | H22: 922 | I22: 4.4 | J22: https://amazon.com/dp/B0C4FBM6GV | K22: =HYPERLINK(J22) -> https://amazon.com/dp/B0C4FBM6GV
A23: MugEasy Endoscope Hook Magnet Side View Mirror Kit Tools for MugEasy Endoscope Camera with Light - Black (6 pcs) | B23: B0D9D8TWZB | C23: 16.864 | D23: 2023.68 | E23: 168.64 | F23: 120 | G23: 10 | H23: 3 | I23: 3.1 | J23: https://amazon.com/dp/B0D9D8TWZB | K23: =HYPERLINK(J23) -> https://amazon.com/dp/B0D9D8TWZB
A24: Endoscope Camera with Light, 1920P HD Bore Scope Borescope with 8 Lights, Waterproof 16.4FT Semi-Rigid Cord for Pipe Inspection, Industrial Endoscope for Phones(Blue) | B24: B0C5M8SRQ8 | C24: 28.715556 | D24: 3101.28 | E24: 258.44 | F24: 108 | G24: 9 | H24: 921 | I24: 4.3 | J24: https://amazon.com/dp/B0C5M8SRQ8 | K24: =HYPERLINK(J24) -> https://amazon.com/dp/B0C5M8SRQ8
A25: Endoscope Camera with Light, 1920P HD Bore Scope Borescope with 8 Lights, Waterproof 16.4FT Semi-Rigid Cord for Pipe Inspection, Industrial Endoscope for Phones(Yellow) | B25: B0C5M7ZH65 | C25: 29.99 | D25: 0 | E25: 0 | F25: 0 | G25: 0 | H25: 921 | I25: 4.3 | J25: https://amazon.com/dp/B0C5M7ZH65 | K25: =HYPERLINK(J25) -> https://amazon.com/dp/B0C5M7ZH65
A26: Total | F26: =SUM(MugEasy!F20:F25) -> 58404 | G26: =SUM(MugEasy!G20:G25) -> 4867

Sheet Teslong
A1: #VALUE!
A7: Rank by Revenue
A8: Product Name | B8: ASIN | C8: Avg Price | D8: Estimated 12mo Revenue | E8: Monthly Rev | F8: Estimated 12mo Units | G8: Monthly Units | H8: # of Reviews | I8: Tool Rating | J8: Column1 | K8: Link
A9: Teslong Two-Way Articulating Borescope with Light, Industrial Endoscope Inspection Camera with Articulated Probe, Flexible Mechanic Fiber Optic Snake Scope Cam for Wall Automotive Engine Inspect-5FT | B9: B0CJY5C9QX | C9: 129.97422 | D9: 3694907.2 | E9: 307908.93 | F9: 28428 | G9: 2369 | H9: 484 | I9: 4.6 | J9: https://amazon.com/dp/B0CJY5C9QX | K9: =HYPERLINK(J9) -> https://amazon.com/dp/B0CJY5C9QX
A10: Teslong Inspection Camera, Dual Lens Borescope Camera with Light, NTS300 5" IPS Industrial Endoscope, 1080P Waterproof Flexible Mechanic Fiber Optic Snake Scope Cam for Wall Automotive Engine (16.5FT) | B10: B07TV2BFVR | C10: 150.13255 | D10: 1075549.6 | E10: 89629.13 | F10: 7164 | G10: 597 | H10: 3464 | I10: 4.6 | J10: https://amazon.com/dp/B07TV2BFVR | K10: =HYPERLINK(J10) -> https://amazon.com/dp/B07TV2BFVR
A11: Teslong Articulating Borescope with Dual Lens Endoscope Camera, Two-Way Articulated Industrial Inspection Camera with LED Light, Flexible Mechanic Fiber Optic Snake Scope Cam for Wall Automotive-5FT | B11: B0CJY6SWBN | C11: 144.43506 | D11: 825013.08 | E11: 68751.09 | F11: 5712 | G11: 476 | H11: 200 | I11: 4.5 | J11: https://amazon.com/dp/B0CJY6SWBN | K11: =HYPERLINK(J11) -> https://amazon.com/dp/B0CJY6SWBN
A12: 50FT Sewer Inspection Camera, Teslong USB C Drain Plumbing Snake Borescope Endoscope Camera with 8 LEDs, 50 ft Flexible Waterproof Fiber Optic Scope Cam Compatible with iPhone 15/16, Android Phone | B12: B0CL4KT182 | C12: 39.989022 | D12: 618550.2 | E12: 51545.85 | F12: 15468 | G12: 1289 | H12: 377 | I12: 3.9 | J12: https://amazon.com/dp/B0CL4KT182 | K12: =HYPERLINK(J12) -> https://amazon.com/dp/B0CL4KT182
A13: Teslong Rifle Borescope, Bore Camera Gun Cleaning Camera - Fits .20 Caliber & Larger-Hunting Shooting Firearms Visual Barrel Inspection Tool w/3 Right-Angle Mirrors and Carrying Case(45inch-Flexible) | B13: B07TTQF24F | C13: 55.981041 | D13: 470912.52 | E13: 39242.71 | F13: 8412 | G13: 701 | H13: 1990 | I13: 4.4 | J13: https://amazon.com/dp/B07TTQF24F | K13: =HYPERLINK(J13) -> https://amazon.com/dp/B07TTQF24F
A14: Teslong Inspection Camera, Dual Lens Borescope Camera with Light, NTS300 5" IPS Industrial Endoscope, 1080P Waterproof Flexible Mechanic Fiber Optic Snake Scope Cam for Wall Automotive Engine (3.3FT) | B14: B08519F2W9 | C14: 131.28759 | D14: 261524.88 | E14: 21793.74 | F14: 1992 | G14: 166 | H14: 3464 | I14: 4.6 | J14: https://amazon.com/dp/B08519F2W9 | K14: =HYPERLINK(J14) -> https://amazon.com/dp/B08519F2W9
A15: Teslong Inspection Camera, Dual Lens Borescope Camera with Light, NTS300 5" IPS Industrial Endoscope, 1080P Waterproof Flexible Mechanic Fiber Optic Snake Scope Cam for Wall Automotive Engine (10FT) | B15: B08519V6GW | C15: 143.49485 | D15: 170471.88 | E15: 14205.99 | F15: 1188 | G15: 99 | H15: 3464 | I15: 4.6 | J15: https://amazon.com/dp/B08519V6GW | K15: =HYPERLINK(J15) -> https://amazon.com/dp/B08519V6GW
A16: 5mm Dual Lens Inspection Camera, Teslong Borescope with LED Light, HD Industrial Endoscope, 5" IPS Screen, Waterproof Video Scope Camera, Flexible Cable for Home/Automotive/Pipe/Car/Wall(5FT) | B16: B09Y1F2MPB | C16: 95.923386 | D16: 146187.24 | E16: 12182.27 | F16: 1524 | G16: 127 | H16: 699 | I16: 4.6 | J16: https://amazon.com/dp/B09Y1F2MPB | K16: =HYPERLINK(J16) -> https://amazon.com/dp/B09Y1F2MPB
A17: Teslong Endoscope Borescope with Light, Snake Inspection Camera for Automotive Engine, Home Waterproof Fiber Optic Camera for Sewer and Duct Pipe (16.5FT) | B17: B0DK965BZP | C17: 49.992769 | D17: 145179 | E17: 12098.25 | F17: 2904 | G17: 242 | H17: 67 | I17: 4.7 | J17: https://amazon.com/dp/B0DK965BZP | K17: =HYPERLINK(J17) -> https://amazon.com/dp/B0DK965BZP
A18: Dual Lens Endoscope Camera with Light, Teslong 4.5" HD Snake Borescope Inspection Camera, Automotive Scope Camera with Flexible Cable, Home Waterproof Fiber Optic for Sewer Drain Pipe (16.5FT) | B18: B086X1XGN1 | C18: 79.855556 | D18: 137990.4 | E18: 11499.2 | F18: 1728 | G18: 144 | H18: 2233 | I18: 4.4 | J18: https://amazon.com/dp/B086X1XGN1 | K18: =HYPERLINK(J18) -> https://amazon.com/dp/B086X1XGN1
A19: 50ft Sewer Camera, Teslong 1080P Drain Plumbing Snake Inspection Camera with Light, 50 ft Flexible Borescope Endoscope Duct Fiber Optic Scope Cam | B19: B08QCMT89N | C19: 110.18175 | D19: 128251.56 | E19: 10687.63 | F19: 1164 | G19: 97 | H19: 2233 | I19: 4.4 | J19: https://amazon.com/dp/B08QCMT89N | K19: =HYPERLINK(J19) -> https://amazon.com/dp/B08QCMT89N
A20: Dual Lens Endoscope Camera with Light, Teslong Mechanic Borescope Inspection Camera with Monitor, Flexible Snake Probe Camera, Fiber Optic Scope for Automotive HVAC Drain Wall | B20: B09N8HSSW1 | C20: 64.843022 | D20: 108158.16 | E20: 9013.18 | F20: 1668 | G20: 139 | H20: 334 | I20: 4.6 | J20: https://amazon.com/dp/B09N8HSSW1 | K20: =HYPERLINK(J20) -> https://amazon.com/dp/B09N8HSSW1
... A31: Borescope Camera with Light, Teslong USB C Snake Endoscope Inspection Camera with 8 LEDs, Flexible Waterproof Drain Camera Fiber Optic Scope Cam Compatible with iPhone 15, Android Phone (16.5FT) | B31: B0D5XM8B12 | C31: 31.964362 | D31: 36055.8 | E31: 3004.65 | F31: 1128 | G31: 94 | H31: 243 | I31: 4.3 | J31: https://amazon.com/dp/B0D5XM8B12 | K31: =HYPERLINK(J31) -> https://amazon.com/dp/B0D5XM8B12
A32: Teslong NTS300 Dual Lens Endoscope with 360° Rotation Probe, 5-Inch Industrial Borescope Inspection Camera with High Brightness 8 LEDs, 16.5FT Waterproof Flexible Mechanics Snake Scope Fiber Optic Cam | B32: B0DH1X8ST7 | C32: 184.4075 | D32: 35406.24 | E32: 2950.52 | F32: 192 | G32: 16 | J32: https://amazon.com/dp/B0DH1X8ST7 | K32: =HYPERLINK(J32) -> https://amazon.com/dp/B0DH1X8ST7
A33: Triple Lens Inspection Camera, Teslong Borescope with LED Light, HD Industrial Endoscope, 5" IPS Screen, Waterproof Video Scope Camera, Flexible Cable for Home/Automotive/Pipe/Car/Wall (16.5FT) | B33: B09BZF4KT8 | C33: 107.83182 | D33: 28467.6 | E33: 2372.3 | F33: 264 | G33: 22 | H33: 123 | I33: 4.6 | J33: https://amazon.com/dp/B09BZF4KT8 | K33: =HYPERLINK(J33) -> https://amazon.com/dp/B09BZF4KT8
A34: Dual Lens Endoscope Camera with Light, Teslong 4.3" HD Snake Borescope Inspection Camera, Automotive Scope Camera with Flexible Cable, Home Waterproof Fiber Optic for Sewer Drain Pipe (16.5FT) | B34: B0DGGM7X88 | C34: 84.8288 | D34: 25448.64 | E34: 2120.72 | F34: 300 | G34: 25 | H34: 57 | I34: 4.8 | J34: https://amazon.com/dp/B0DGGM7X88 | K34: =HYPERLINK(J34) -> https://amazon.com/dp/B0DGGM7X88
A35: Triple Lens Borescope Inspection Camera, Teslong Professional Endoscope with Light, Digital Video Scope Camera, 5" IPS Screen, Waterproof Flexible Cable for Automotive/Home/Wall/Pipe/Car (16.5FT) | B35: B07Q86XGN2 | C35: 171.405 | D35: 24682.32 | E35: 2056.86 | F35: 144 | G35: 12 | H35: 326 | I35: 4.6 | J35: https://amazon.com/dp/B07Q86XGN2 | K35: =HYPERLINK(J35) -> https://amazon.com/dp/B07Q86XGN2
A36: Teslong Telescopic Camera with Light, USB-C Borescope with 5FT Telescopic Pole, for HVAC Systems, Wall, Chimney, Automotive and Pipe Inspections, Compatible with iPhone 15/16 and Android | B36: B0DL621NQ2 | C36: 51.845278 | D36: 22397.16 | E36: 1866.43 | F36: 432 | G36: 36 | H36: 49 | I36: 4.2 | J36: https://amazon.com/dp/B0DL621NQ2 | K36: =HYPERLINK(J36) -> https://amazon.com/dp/B0DL621NQ2
A37: Teslong 2.0MP HD AF Auto Focus Borescope, 16.5ft Flexible Endoscope with Adjustable Lights, USB-C Inspection Camera for Plumbing, Automotive, Wall, for iPhone 15/16 & Android, Long Focus & Autofocus | B37: B0DL8LJTWM | C37: 40.741795 | D37: 19067.16 | E37: 1588.93 | F37: 468 | G37: 39 | H37: 40 | I37: 4.5 | J37: https://amazon.com/dp/B0DL8LJTWM | K37: =HYPERLINK(J37) -> https://amazon.com/dp/B0DL8LJTWM
A38: Teslong Two-Way Articulating Borescope with Light, USB-C Endoscope Camera for Automotive Mechanics, 5FT Flexible Fiber Optic Snake Inspection Camera Scope, Compatible with iPhone 15/16 and Android | B38: B0DGG5RBC3 | C38: 78.3915 | D38: 18813.96 | E38: 1567.83 | F38: 240 | G38: 20 | H38: 27 | I38: 3.9 | J38: https://amazon.com/dp/B0DGG5RBC3 | K38: =HYPERLINK(J38) -> https://amazon.com/dp/B0DGG5RBC3
A39: 5mm Dual Lens Inspection Camera, Teslong Borescope with LED Light, HD Industrial Endoscope, 5" IPS Screen, Waterproof Video Scope Camera, Flexible Cable for Home/Automotive/Pipe/Car/Wall(16.5FT) | B39: B08PTVBGBQ | C39: 130.31333 | D39: 18765.12 | E39: 1563.76 | F39: 144 | G39: 12 | H39: 699 | I39: 4.6 | J39: https://amazon.com/dp/B08PTVBGBQ | K39: =HYPERLINK(J39) -> https://amazon.com/dp/B08PTVBGBQ
A40: USB C Endoscope Camera with Light, Teslong Type-C Snake Borescope Camera with 8 LED Lights, 5FT Flexible Waterproof Inspection Camera, Fiber Optic Scope Compatible with iPhone 15/16, Android Phone | B40: B0CCQXK5JV | C40: 27.715 | D40: 16629 | E40: 1385.75 | F40: 600 | G40: 50 | H40: 818 | I40: 4.3 | J40: https://amazon.com/dp/B0CCQXK5JV | K40: =HYPERLINK(J40) -> https://amazon.com/dp/B0CCQXK5JV
A41: Dual Lens Endoscope Camera with Light, Teslong 4.5" HD Snake Borescope Inspection Camera, Automotive Scope Camera with Flexible Cable, Home Waterproof Fiber Optic for Sewer Drain Pipe (10FT) | B41: B0DH1MDYG9 | C41: 89.751333 | D41: 16155.24 | E41: 1346.27 | F41: 180 | G41: 15 | H41: 2233 | I41: 4.4 | J41: https://amazon.com/dp/B0DH1MDYG9 | K41: =HYPERLINK(J41) -> https://amazon.com/dp/B0DH1MDYG9
A42: Dual Lens Endoscope with Light, Teslong USB-C Borescope Inspection Camera with 8+1 LED Light, Flexible Waterproof Fiber Optic Camera Snake Scope Compatible with iPhone 15, Android Phone(16.5FT) | B42: B0CL4MJ6NK | C42: 40.4765 | D42: 9714.36 | E42: 809.53 | F42: 240 | G42: 20 | H42: 244 | I42: 4.5 | J42: https://amazon.com/dp/B0CL4MJ6NK | K42: =HYPERLINK(J42) -> https://amazon.com/dp/B0CL4MJ6NK
